Workbook

Sheet Entidades
A1: Entidades públicas: poder, presupuesto y posibles duplicidades
A2: 135 registros: 76 estatales + 3 creaciones legales de constitución no confirmada + 3 creaciones anunciadas o en tramitación, no constituidas + 53 autonómicos. Creados o transformados desde 2004. Inventario parcial, no censo exhaustivo. Las filas 127 a 136 de Hoja 1 (fondo verde) son altas del 14/10/2026.
A3: Columnas numéricas en EUR millones: 44,3 = 44,3 millones de euros. El texto original puede conservar euros. Vacío = sin cifra propia verificada; nunca sustituir por cero. Filtrar año y base antes de sumar. Duplicidad es un juicio de relación, NO una prueba de gasto inútil o doble financiación. Personal ocupado, puestos aprobados, crédito de personal y gasto ejecutado son medidas separadas; no sumar distintos años. Consulta: preceptivo no significa vinculante. No equivale a veto; distinguir ley, reglamento y plan. Pendiente no significa NO. La consulta o audiencia a asociaciones no significa consentimiento obligatorio (Ley 50/1997, art. 26.6). Revisados125 casos de consulta a nivel de las fuentes citadas;0 pendientes de esta pasada. No auditoría exhaustiva de toda la normativa sectorial. Informes preceptivos sectoriales verificados en varios órganos actuales e históricos; no equivalen a vetos. Pasada de consulta finalizada en las fuentes citadas. Personal ejecutado: obligaciones reconocidas cap1 hasta31/08/2026,8meses, no salario puro ni año completo. Pagos separados; ninguna ausencia sustituida por0. Añadido cierre2025:19 entidades con gasto anual cap1, separado de2026parcial. Emergencias: personas y crédito solo programa2.2.B, NO agencia entera.
A4: Resumen 2026 por base: suma propia verificada EUR millones y número de registros; NO sumar bases mezcladas
B5: Crédito total actualizado | C5: =SUMIFS('Hoja 1'!K2:K136,'Hoja 1'!L2:L136,2026,'Hoja 1'!M2:M136,B5) -> 10829.239 | D5: =COUNTIFS('Hoja 1'!L2:L136,2026,'Hoja 1'!M2:M136,B5,'Hoja 1'!K2:K136,">0") -> 24 | E5: ="Personal 2026 reconocido hasta 31/08 (IGAE), EUR millones ("&COUNTIFS('Hoja 1'!AQ2:AQ136,"<>",'Hoja 1'!AS2:AS136,"Hasta 31/08/2026:8 meses, NO año completo")&" entidades; NO salarios puros; otros cortes en Hoja 1, no se suman)" -> Personal 2026 reconocido hasta 31/08 (IGAE), EUR millones (22 entidades; NO salarios puros; otros cortes en Hoja 1, no se suman) | F5: =SUMIFS('Hoja 1'!AQ2:AQ136,'Hoja 1'!AR2:AR136,2026,'Hoja 1'!AS2:AS136,"Hasta 31/08/2026:8 meses, NO año completo") -> 737.209
B6: Crédito inicial aprobado | C6: =SUMIFS('Hoja 1'!K2:K136,'Hoja 1'!L2:L136,2026,'Hoja 1'!M2:M136,B6) -> 1002.092 | D6: =COUNTIFS('Hoja 1'!L2:L136,2026,'Hoja 1'!M2:M136,B6,'Hoja 1'!K2:K136,">0") -> 15 | E6: ="Pagos personal 2026 hasta 31/08, EUR millones ("&COUNT('Hoja 1'!BI2:BI136)&" entidades)" -> Pagos personal 2026 hasta 31/08, EUR millones (22 entidades) | F6: =SUM('Hoja 1'!BI2:BI136) -> 736.825
B7: Presupuesto propio aprobado | C7: =SUMIFS('Hoja 1'!K2:K136,'Hoja 1'!L2:L136,2026,'Hoja 1'!M2:M136,B7) -> 792.46274 | D7: =COUNTIFS('Hoja 1'!L2:L136,2026,'Hoja 1'!M2:M136,B7,'Hoja 1'!K2:K136,">0") -> 20 | E7: ="Gasto de personal 2025, año completo (cap.1 obligaciones; gastos de personal de cuentas en fundaciones/entes): "&COUNT('Hoja 1'!BP2:BP136)&" entidades, EUR millones; NO sumar con parcial 2026" -> Gasto de personal 2025, año completo (cap.1 obligaciones; gastos de personal de cuentas en fundaciones/entes): 27 entidades, EUR millones; NO sumar con parcial 2026 | F7: =SUM('Hoja 1'!BP2:BP136) -> 1144.5759
A9: Cobertura de campos en Hoja 1 (número de fichas con dato; 135 en total)
B10: Presupuesto propio (cualquier año/base) | C10: =COUNT('Hoja 1'!K2:K136) -> 61
B11: Sin presupuesto propio verificado en norma (órganos sin dotación) | C11: =COUNTIF('Hoja 1'!O2:O136,"Sin presupuesto propio: órgano*") -> 45
B12: Extinguidas / suprimidas | C12: =COUNTIF('Hoja 1'!O2:O136,"Sin presupuesto propio actual: supresión*") -> 10
B13: Sin cifra propia actual verificada (pendientes) | C13: =COUNTIF('Hoja 1'!O2:O136,"Sin cifra propia actual verificada") -> 14
B14: Crédito de personal (cap. 1 o gastos de personal) | C14: =COUNT('Hoja 1'!AL2:AL136) -> 44
B15: Gasto de personal ejecutado, columna AQ (año y corte variables; no sumar) | C15: =COUNT('Hoja 1'!AQ2:AQ136) -> 33
B16: Gasto de personal 2025 año completo | C16: =COUNT('Hoja 1'!BP2:BP136) -> 27
B17: Personas ocupadas (fecha variable; no sumar) | C17: =COUNT('Hoja 1'!AG2:AG136) -> 29
B18: Puestos aprobados / presupuestados | C18: =COUNT('Hoja 1'!AX2:AX136) -> 22
A20: Celdas con fondo amarillo en Hoja 1: completadas o corregidas el 12/10/2026. Filas con fondo verde: entidades añadidas el 14/10/2026. Detalle celda a celda en la hoja "Cambios 12-10-2026"; fuentes, páginas y huecos pendientes en "Verificación y pendientes".
A22: Clasificación de las 135 fichas según el P100 de Extramuros (juicio con criterios explícitos; motivo, base en el P100 y destino de cada una en Hoja 1)
C23: Fichas | D23: Con presupuesto propio 2026 | E23: Suma de presupuestos propios 2026, EUR millones (bases distintas: orden de magnitud, no total contable)
A24: Binario | B24: Útil | C24: =COUNTIF('Hoja 1'!BV2:BV136,B24) -> 32 | D24: =COUNTIFS('Hoja 1'!BV2:BV136,B24,'Hoja 1'!L2:L136,2026,'Hoja 1'!K2:K136,">0") -> 29 | E24: =SUMIFS('Hoja 1'!K2:K136,'Hoja 1'!BV2:BV136,B24,'Hoja 1'!L2:L136,2026) -> 10202.391
B25: No útil | C25: =COUNTIF('Hoja 1'!BV2:BV136,B25) -> 86 | D25: =COUNTIFS('Hoja 1'!BV2:BV136,B25,'Hoja 1'!L2:L136,2026,'Hoja 1'!K2:K136,">0") -> 29 | E25: =SUMIFS('Hoja 1'!K2:K136,'Hoja 1'!BV2:BV136,B25,'Hoja 1'!L2:L136,2026) -> 2340.3934
B26: Sin decisión en el P100 | C26: =COUNTIF('Hoja 1'!BV2:BV136,B26) -> 4 | D26: =COUNTIFS('Hoja 1'!BV2:BV136,B26,'Hoja 1'!L2:L136,2026,'Hoja 1'!K2:K136,">0") -> 1 | E26: =SUMIFS('Hoja 1'!K2:K136,'Hoja 1'!BV2:BV136,B26,'Hoja 1'!L2:L136,2026) -> 81.00922
B27: Extinguida | C27: =COUNTIF('Hoja 1'!BV2:BV136,B27) -> 13 | D27: =COUNTIFS('Hoja 1'!BV2:BV136,B27,'Hoja 1'!L2:L136,2026,'Hoja 1'!K2:K136,">0") -> 0 | E27: =SUMIFS('Hoja 1'!K2:K136,'Hoja 1'!BV2:BV136,B27,'Hoja 1'!L2:L136,2026) -> 0
A28: Veredicto | B28: Mantener | C28: =COUNTIF('Hoja 1'!BW2:BW136,B28) -> 28 | D28: =COUNTIFS('Hoja 1'!BW2:BW136,B28,'Hoja 1'!L2:L136,2026,'Hoja 1'!K2:K136,">0") -> 25 | E28: =SUMIFS('Hoja 1'!K2:K136,'Hoja 1'!BW2:BW136,B28,'Hoja 1'!L2:L136,2026) -> 9098.9938
B29: Reformar | C29: =COUNTIF('Hoja 1'!BW2:BW136,B29) -> 4 | D29: =COUNTIFS('Hoja 1'!BW2:BW136,B29,'Hoja 1'!L2:L136,2026,'Hoja 1'!K2:K136,">0") -> 4 | E29: =SUMIFS('Hoja 1'!K2:K136,'Hoja 1'!BW2:BW136,B29,'Hoja 1'!L2:L136,2026) -> 1103.3969
B30: Integrar | C30: =COUNTIF('Hoja 1'!BW2:BW136,B30) -> 34 | D30: =COUNTIFS('Hoja 1'!BW2:BW136,B30,'Hoja 1'!L2:L136,2026,'Hoja 1'!K2:K136,">0") -> 27 | E30: =SUMIFS('Hoja 1'!K2:K136,'Hoja 1'!BW2:BW136,B30,'Hoja 1'!L2:L136,2026) -> 2263.5233
B31: Suprimir | C31: =COUNTIF('Hoja 1'!BW2:BW136,B31) -> 52 | D31: =COUNTIFS('Hoja 1'!BW2:BW136,B31,'Hoja 1'!L2:L136,2026,'Hoja 1'!K2:K136,">0") -> 2 | E31: =SUMIFS('Hoja 1'!K2:K136,'Hoja 1'!BW2:BW136,B31,'Hoja 1'!L2:L136,2026) -> 76.87014
B32: Pendiente de decisión | C32: =COUNTIF('Hoja 1'!BW2:BW136,B32) -> 4 | D32: =COUNTIFS('Hoja 1'!BW2:BW136,B32,'Hoja 1'!L2:L136,2026,'Hoja 1'!K2:K136,">0") -> 1 | E32: =SUMIFS('Hoja 1'!K2:K136,'Hoja 1'!BW2:BW136,B32,'Hoja 1'!L2:L136,2026) -> 81.00922
B33: Extinguida | C33: =COUNTIF('Hoja 1'!BW2:BW136,B33) -> 13 | D33: =COUNTIFS('Hoja 1'!BW2:BW136,B33,'Hoja 1'!L2:L136,2026,'Hoja 1'!K2:K136,">0") -> 0 | E33: =SUMIFS('Hoja 1'!K2:K136,'Hoja 1'!BW2:BW136,B33,'Hoja 1'!L2:L136,2026) -> 0
A34: Función | B34: Servicio público directo | C34: =COUNTIF('Hoja 1'!BX2:BX136,B34) -> 31 | D34: =COUNTIFS('Hoja 1'!BX2:BX136,B34,'Hoja 1'!L2:L136,2026,'Hoja 1'!K2:K136,">0") -> 24 | E34: =SUMIFS('Hoja 1'!K2:K136,'Hoja 1'!BX2:BX136,B34,'Hoja 1'!L2:L136,2026) -> 3739.0019
B35: Regulación o inspección de terceros | C35: =COUNTIF('Hoja 1'!BX2:BX136,B35) -> 15 | D35: =COUNTIFS('Hoja 1'!BX2:BX136,B35,'Hoja 1'!L2:L136,2026,'Hoja 1'!K2:K136,">0") -> 15 | E35: =SUMIFS('Hoja 1'!K2:K136,'Hoja 1'!BX2:BX136,B35,'Hoja 1'!L2:L136,2026) -> 5433.3363
B36: Financiación y ayudas | C36: =COUNTIF('Hoja 1'!BX2:BX136,B36) -> 14 | D36: =COUNTIFS('Hoja 1'!BX2:BX136,B36,'Hoja 1'!L2:L136,2026,'Hoja 1'!K2:K136,">0") -> 11 | E36: =SUMIFS('Hoja 1'!K2:K136,'Hoja 1'!BX2:BX136,B36,'Hoja 1'!L2:L136,2026) -> 3405.5617
B37: Control interno y cumplimiento | C37: =COUNTIF('Hoja 1'!BX2:BX136,B37) -> 13 | D37: =COUNTIFS('Hoja 1'!BX2:BX136,B37,'Hoja 1'!L2:L136,2026,'Hoja 1'!K2:K136,">0") -> 9 | E37: =SUMIFS('Hoja 1'!K2:K136,'Hoja 1'!BX2:BX136,B37,'Hoja 1'!L2:L136,2026) -> 45.893442
B38: Consultivo o participación | C38: =COUNTIF('Hoja 1'!BX2:BX136,B38) -> 46 | D38: =COUNTIFS('Hoja 1'!BX2:BX136,B38,'Hoja 1'!L2:L136,2026,'Hoja 1'!K2:K136,">0") -> 0 | E38: =SUMIFS('Hoja 1'!K2:K136,'Hoja 1'!BX2:BX136,B38,'Hoja 1'!L2:L136,2026) -> 0
B39: Extinguida o no constituida | C39: =COUNTIF('Hoja 1'!BX2:BX136,B39) -> 16 | D39: =COUNTIFS('Hoja 1'!BX2:BX136,B39,'Hoja 1'!L2:L136,2026,'Hoja 1'!K2:K136,">0") -> 0 | E39: =SUMIFS('Hoja 1'!K2:K136,'Hoja 1'!BX2:BX136,B39,'Hoja 1'!L2:L136,2026) -> 0
A40: Base en el P100
B41: Explícito: el P100 nombra el organismo o su categoría | C41: =COUNTIF('Hoja 1'!CC2:CC136,"Explícito*") -> 63
B42: Aplicando el criterio del P100 (deducción nuestra) | C42: =COUNTIF('Hoja 1'!CC2:CC136,"Aplicando*") -> 55
B43: El P100 no trata la materia | C43: =COUNTIF('Hoja 1'!CC2:CC136,"El P100*") -> 4
...

Sheet Duplicidades por tema
A1: Tema | B1: Organismo estatal | C1: Andalucía | D1: Aragón | E1: Asturias | F1: Illes Balears | G1: Canarias | H1: Cantabria | I1: Castilla-La Mancha | J1: Castilla y León | K1: Cataluña | L1: Comunitat Valenciana | M1: Extremadura | N1: Galicia | O1: Madrid | P1: Murcia | Q1: Navarra | R1: País Vasco | S1: La Rioja | T1: CCAA con organismo propio | U1: CCAA sin verificar | V1: Organismos en total (Estado + CCAA, verificados) | W1: ¿Cubre el Estado esos territorios? | X1: Base competencial | Y1: Fuentes
A2: Agencias tributarias | B2: Agencia Estatal de Administración Tributaria (AEAT) | C2: Propio (ente): Agencia Tributaria de Andalucía (ATRIAN) | D2: Consejería | E2: Propio (ente): Ente Público de Servicios Tributarios del Principado de Asturias ('Tributas en Asturias') | F2: Propio (ente): Agencia Tributaria de las Illes Balears (ATIB) | G2: Propio (ente): Agencia Tributaria Canaria (ATC) | H2: Propio (ente): Agencia Cántabra de Administración Tributaria (ACAT) | I2: Consejería | J2: Consejería | K2: Propio (ente): Agència Tributària de Catalunya (ATC) | L2: Propio (ente): Agència Tributària Valenciana (ATV) | M2: Consejería | N2: Propio (ente): Axencia Tributaria de Galicia (ATRIGA) | O2: Consejería | P2: Propio (ente): Agencia Tributaria de la Región de Murcia (ATRM) | Q2: Propio (ente): Hacienda Foral de Navarra (organismo autónomo) | R2: Propio (órgano): Haciendas Forales de Álava, Bizkaia y Gipuzkoa (departamentos de Hacienda de las tres diputaciones forales) + Órgano de Coordinación Tributaria de Euskadi | S2: Consejería | T2: =COUNTIF(C2:S2,"Propio*") -> 11 | U2: =COUNTIF(C2:S2,"Sin verificar") -> 0 | V2: =1+T2 -> 12 | W2: Parcial. La AEAT cubre en todo el territorio común los tributos estatales no cedidos, pero los tributos cedidos los gestiona cada CA por ley, con agencia o con su DG. La función autonómica existe en las 15 CCAA de régimen común: la 'duplicidad' de las 10 agencias es de forma organizativa, no de función, porque las 6 CCAA sin agencia hacen lo mismo desde una DG. En territorio foral la AEAT no gestiona los tributos concertados o convenidos. | X2: Tributos cedidos: por la LOFCA y la ley de financiación autonómica, las CCAA de régimen común aplican por delegación los tributos cedidos (ISD, ITPAJD, tributos sobre el juego, etc.) y organizan libremente su administración tributaria (agencia o DG). La AEAT aplica los tributos estatales (IRPF, IVA, IS, IIEE) en todo el territorio común. Navarra (Convenio Económico) y el País Vasco (Concierto Económico, Ley 12/2002) tienen haciendas forales propias por la DA 1ª de la Constitución. | Y2: https://www.boe.es/eli/es-an/l/2007/12/18/23/con https://laadministracionaldia.inap.es/noticia.asp?id=1232456 https://www.boe.es/eli/es-ib/l/2008/04/14/3 https://boe.es/buscar/act.php?id=BOE-A-2014-9902 https://www.parcan.es/files/documentacion/dosieres/DOSS0221/DOSS0221DOC4682.PDF https://transparencia.castillalamancha.es/titular/33680 https://www.boe.es/diario_boe/txt.php?id=BOE-A-2007-15212 https://laadministracionaldia.inap.es/noticia.asp?id=1256956 https://doe.juntaex.es/pdfs/doe/2026/790o/26060892.pdf https://www.es.parlamentodegalicia.gal/sitios/web/BibliotecaLeisdeGalicia/Lei_15_2010.pdf https://www.comunidad.madrid/transparencia/unidad-organizativa-responsable/direccion-general-tributos https://www.parcan.es/files/documentacion/dosieres/DOSS0221/DOSS0221DOC4791.PDF https://laadministracionaldia.inap.es/noticia.asp?id=1239023 https://www.euskadi.eus/gobierno-vasco/contenidos/informacion/fisc_sytribvas/es_3222/indice_c.html https://larioja.org/tributos/en/enlaces-interes/competencias-direccion-general-tributos https://www.gobierno.jcyl.es/web/es/consejerias/direccion-general-tributos-financiacion.html https://gd.aragon.es/cgi-bin/ORGA/BRSCGI?CMD=VERDOC&BASE=ORGA&PIECE=ORGA&SEC=ORGABUSXI&DOCN=653
A3: Consejos de transparencia | B3: Consejo de Transparencia y Buen Gobierno (CTBG) | C3: Propio (ente): Consejo de Transparencia y Protección de Datos de Andalucía (CTPDA) | D3: Propio (órgano): Consejo de Transparencia de Aragón | E3: Lo cubre el Estado | F3: Lo cubre el Estado | G3: Propio (órgano): Comisionado de Transparencia y Acceso a la Información Pública de Canarias | H3: Lo cubre el Estado | I3: Propio (órgano): Consejo Regional de Transparencia y Buen Gobierno de Castilla-La Mancha | J3: Propio (órgano): Comisionado de Transparencia de Castilla y León (función atribuida al Procurador del Común) | K3: Propio (órgano): Comissió de Garantia del Dret d'Accés a la Informació Pública (GAIP) | L3: Propio (órgano): Consell de Transparència de la Comunitat Valenciana | M3: Lo cubre el Estado | N3: Propio (órgano): Comisión da Transparencia de Galicia | O3: Propio (órgano): Consejo de Transparencia y Protección de Datos de la Comunidad de Madrid | P3: Propio (órgano): Comisionado de Transparencia de la Región de Murcia | Q3: Propio (órgano): Consejo de Transparencia de Navarra | R3: Propio (órgano): Comisión Vasca de Acceso a la Información Pública | S3: Lo cubre el Estado | T3: =COUNTIF(C3:S3,"Propio*") -> 12 | U3: =COUNTIF(C3:S3,"Sin verificar") -> 0 | V3: =1+T3 -> 13 | W3: Sí, por convenio. En 2025-2026 el CTBG resuelve las reclamaciones de Asturias (nuevo convenio de 11/05/2026), Illes Balears (convenio 2025-2029), Cantabria, Extremadura y La Rioja, además de Ceuta y Melilla. La CA paga por reclamación resuelta (192,35 EUR en el convenio asturiano). CLM (hasta 31/10/2023) y Madrid (hasta 02/11/2021) dejaron el convenio al crear su órgano. | X3: Transparencia: cada administración puede atribuir la resolución de las reclamaciones de acceso a un órgano propio o convenirla con el CTBG (Ley 19/2013, art. 24 y DA 4ª). | Y3: https://consejodetransparencia.es/content/dam/ctransparencia/portal-ctbg/nosotros/cooperacion/acta_constitucion_COTAI.pdf https://consejodetransparencia.es/content/dam/ctransparencia/portal-ctbg/nosotros/memorias-y-plan-estrategico/memoria-2025/Memoria_2025_CTBG.pdf https://consejodetransparencia.es/content/dam/ctransparencia/portal-ctbg/nosotros/memorias-y-plan-estrategico/memoria-2025/Resumen_Ejecutivo_Memoria_2025_CTBG.pdf https://www.asturias.es/bopa/2026/06/26/2026-05300.pdf https://www.bocm.es/boletin/CM_Orden_BOCM/2024/05/23/BOCM-20240523-1.PDF https://www.comunidad.madrid/transparencia/sites/default/files/8._main_reglamento_ctpd.pdf https://boe.es/ccaa/borm/2024/158/s20598-20604.pdf https://www.boe.es/buscar/act.php?id=BOE-A-2014-7534
A4: Autoridades de protección de datos | B4: Agencia Española de Protección de Datos (AEPD) | C4: Propio (ente): Consejo de Transparencia y Protección de Datos de Andalucía (CTPDA) | D4: Lo cubre el Estado | E4: Lo cubre el Estado | F4: Lo cubre el Estado | G4: Lo cubre el Estado | H4: Lo cubre el Estado | I4: Lo cubre el Estado | J4: Lo cubre el Estado | K4: Propio (ente): Autoritat Catalana de Protecció de Dades (APDCAT) | L4: Lo cubre el Estado | M4: Lo cubre el Estado | N4: Lo cubre el Estado | O4: Lo cubre el Estado | P4: Lo cubre el Estado | Q4: Lo cubre el Estado | R4: Propio (ente): Autoridad Vasca de Protección de Datos (AVPD) | S4: Lo cubre el Estado | T4: =COUNTIF(C4:S4,"Propio*") -> 3 | U4: =COUNTIF(C4:S4,"Sin verificar") -> 0 | V4: =1+T4 -> 4 | W4: Sí, por defecto y por ley: la AEPD supervisa el sector público autonómico y local de las 14 CCAA sin autoridad propia, y a todo el sector privado en toda España. Madrid suprimió su agencia el 01/01/2013 y la AEPD asumió sus funciones. | X4: Protección de datos: el RGPD y la LOPDGDD (arts. 57-58) permiten a las CCAA crear autoridades de control para los tratamientos de su sector público y de las entidades locales de su territorio. En lo demás, y donde no las hay, es competente la AEPD. | Y4: https://www.aepd.es/la-agencia/transparencia/informacion-de-caracter-institucional-organizativa-y-de-planificacion/historia https://boe.es/boe/dias/2024/01/18/pdfs/BOE-A-2024-900.pdf https://www.euskadi.eus/web01-bopv/es/bopv2/datos/2024/12/2405865a.shtml https://www.comunidad.madrid/transparencia/sites/default/files/8._main_reglamento_ctpd.pdf
A5: Autoridades de defensa de la competencia | B5: Comisión Nacional de los Mercados y la Competencia (CNMC) | C5: Propio (ente): Agencia de la Competencia y de la Regulación Económica de Andalucía (antes Agencia de Defensa de la Competencia de Andalucía) | D5: Propio (órgano): Tribunal de Defensa de la Competencia de Aragón (resolución) + Servicio de Defensa de la Competencia (instrucción, en el departamento) | E5: Lo cubre el Estado | F5: Lo cubre el Estado | G5: Propio (órgano): Consejo Canario de Defensa de la Competencia (resolución) + Servicio de Defensa de la Competencia (instrucción) | H5: Lo cubre el Estado | I5: Lo cubre el Estado | J5: Propio (órgano): Órgano autonómico de defensa de la competencia de Castilla y León (instrucción + resolución; nombre a confirmar) | K5: Propio (ente): Autoritat Catalana de la Competència (ACCO) | L5: Propio (órgano): Comisión de Defensa de la Competencia de la Comunitat Valenciana | M5: Propio (órgano): Jurado de Defensa de la Competencia de Extremadura | N5: Propio (órgano): Comisión Galega da Competencia (órgano colegiado independiente adscrito al Instituto Galego do Consumo e da Competencia, OA) | O5: Consejería | P5: Consejería | Q5: Consejería | R5: Propio (ente): Autoridad Vasca de la Competencia (AVC) | S5: Lo cubre el Estado | T5: =COUNTIF(C5:S5,"Propio*") -> 9 | U5: =COUNTIF(C5:S5,"Sin verificar") -> 0 | V5: =1+T5 -> 10 | W5: Sí, por defecto: donde no hay órgano autonómico actúa la CNMC, y donde la CA solo instruye (Madrid, Murcia, Navarra) resuelve la CNMC. Los casos se reparten mediante el Consejo de Defensa de la Competencia. | X5: Defensa de la competencia: legislación estatal (Ley 15/2007). Las CCAA con competencia estatutaria ejecutan sobre conductas que afectan solo a su territorio, con puntos de conexión y asignación de casos según la Ley 1/2002 de coordinación; las conductas supraautonómicas corresponden siempre a la CNMC. | Y5: https://cnmc.es/la-cnmc-y-las-autoridades-de-competencia-autonomicas-han-celebrado-en-madrid-el-consejo-anual-de https://www.boe.es/buscar/act.php?id=BOE-A-2007-14406 https://derecholocal.es/?p=11702 https://dogv.gva.es/datos/2012/03/26/pdf/2012_3049.pdf https://laadministracionaldia.inap.es/noticia.asp?id=1057841 https://www.juntaex.es/w/0680923 https://www.lex.gal/es/normativa/detalle/10097/pdf/ https://www.boe.es/buscar/act.php?id=BOE-A-2012-2313 https://cnmc.es/sites/default/files/editor_contenidos/CNMC/Memorias/Resumen-ejecutivo-memoria-2024_.pdf
A6: Oficinas y agencias antifraude y de protección del informante | B6: Autoridad Independiente de Protección del Informante, A.A.I. (AIPI) | C6: Propio (ente): Oficina Andaluza contra el Fraude y la Corrupción (OAAF) | D6: No existe | E6: Propio (ente): Consejo de Transparencia y Buen Gobierno del Principado de Asturias | F6: No existe | G6: No existe | H6: No existe | I6: No existe | J6: Propio (órgano): Autoridad Independiente en materia de Corrupción de Castilla y León (AAICyL) | K6: Propio (ente): Oficina Antifraude de Cataluña (OAC) | L6: Propio (ente): Agencia de Prevención y Lucha contra el Fraude y la Corrupción de la Comunitat Valenciana (AVAF) | M6: No existe | N6: Propio (ente): Autoridad Gallega de Protección de la Persona Informante (AGPI) | O6: Propio (órgano): Consejo de Transparencia y Protección de Datos de la Comunidad de Madrid (CTPD) | P6: No existe | Q6: Propio (ente): Oficina de Buenas Prácticas y Anticorrupción de la Comunidad Foral de Navarra (OANA) | R6: Propio (ente): Autoridad Vasca de Transparencia – Gardena | S6: No existe | T6: =COUNTIF(C6:S6,"Propio*") -> 9 | U6: =COUNTIF(C6:S6,"Sin verificar") -> 0 | V6: =1+T6 -> 10 | W6: parcial: la AIPI cubre el sector público estatal; para el sector público de las CCAA sin autoridad propia requiere convenio con la Consejería competente, y el PAA 2026 no cita ninguno firmado (objetivo de 3 en 2026). Hoy hay 8 CCAA sin autoridad propia ni convenio verificado. | X6: Protección del informante: la Ley 2/2023 (art. 24) permite a cada comunidad designar su propia autoridad independiente para su sector público autonómico y local; si no la designa, la AIPI solo puede actuar en ese territorio mediante convenio (DA 2ª). Las oficinas antifraude previas son creación autonómica por autoorganización (casi todas adscritas al Parlamento). | Y6: https://www.proteccioninformante.gob.es/content/dam/aipi/documentos/PLAN_ACTUACION_ANUAL_2026_AIPI.pdf https://laadministracionaldia.inap.es/noticia.asp?id=1520499 https://www.cepc.gob.es/sites/default/files/2026-06/20260617-aipi.pdf https://laadministracionaldia.inap.es/noticia.asp?id=1249714 https://intranet.caib.es/eboibfront/pdf/es/2024/68/1162692 https://www.comunidad.madrid/consejo-transparencia/canal-externo-informante https://laadministracionaldia.inap.es/noticia.asp?id=1260634 https://www.boe.es/eli/es-ar/l/2017/06/01/5/con
A7: Agencias de calidad universitaria | B7: Agencia Nacional de Evaluación de la Calidad y Acreditación (ANECA) | C7: Propio (ente): Agencia para la Calidad Científica y Universitaria de Andalucía (ACCUA) | D7: Propio (ente): Agencia de Calidad y Prospectiva Universitaria de Aragón (ACPUA) | E7: Lo cubre el Estado | F7: Propio (ente): Agència de Qualitat Universitària de les Illes Balears (AQUIB) | G7: Propio (ente): Agencia Canaria de Calidad Universitaria y Evaluación Educativa (ACCUEE) | H7: Lo cubre el Estado | I7: Lo cubre el Estado | J7: Propio (ente): Agencia para la Calidad del Sistema Universitario de Castilla y León (ACSUCYL) | K7: Propio (ente): Agència per a la Qualitat del Sistema Universitari de Catalunya (AQU Catalunya) | L7: Propio (ente): Agència Valenciana d'Avaluació i Prospectiva (AVAP) | M7: Lo cubre el Estado | N7: Propio (ente): Axencia para a Calidade do Sistema Universitario de Galicia (ACSUG) | O7: Propio (ente): Fundación para el Conocimiento madri+d | P7: Lo cubre el Estado | Q7: Lo cubre el Estado | R7: Propio (ente): Agencia de Calidad del Sistema Universitario Vasco (Unibasq) | S7: Lo cubre el Estado | T7: =COUNTIF(C7:S7,"Propio*") -> 10 | U7: =COUNTIF(C7:S7,"Sin verificar") -> 0 | V7: =1+T7 -> 11 | W7: sí, por defecto: ANECA evalúa en las 7 CCAA sin agencia propia (Asturias, Cantabria, Castilla-La Mancha, Extremadura, Murcia, Navarra, La Rioja). Además las universidades pueden recurrir a cualquier agencia inscrita en EQAR. | X7: Garantía de calidad universitaria: la evaluación y acreditación de títulos e instituciones corresponde a ANECA o a las agencias autonómicas inscritas en EQAR, cada una en su ámbito (normativa universitaria estatal: LOSU y RD 822/2021). Las CCAA pueden crear su agencia; si no la crean, actúa ANECA. | Y7: https://eqar.eu/register/agencies https://www.aneca.es/en/reacu-network https://dogv.gva.es/datos/2024/01/12/pdf/2024_156.pdf https://www.inqaahe.org/wp-content/uploads/2025/02/D250.pdf https://intranet.caib.es/eboibfront/pdf/es/2021/98/1093428
A8: Evaluación de políticas públicas | B8: Agencia Estatal de Evaluación de Políticas Públicas | C8: Consejería | D8: Sin verificar | E8: Sin verificar | F8: Sin verificar | G8: Sin verificar | H8: Sin verificar | I8: Sin verificar | J8: Consejería | K8: Propio (ente): Institut Català d'Avaluació de Polítiques Públiques (Ivàlua) | L8: Sin verificar | M8: Sin verificar | N8: Sin verificar | O8: Sin verificar | P8: Sin verificar | Q8: Propio (órgano): Comisión Foral para la Evaluación de las Políticas Públicas y la Calidad de los Servicios Públicos | R8: Sin verificar | S8: Sin verificar | T8: =COUNTIF(C8:S8,"Propio*") -> 2 | U8: =COUNTIF(C8:S8,"Sin verificar") -> 13 | V8: =1+T8 -> 3 | W8: no: la Agencia estatal evalúa políticas de la AGE. Las CCAA cooperan en la red voluntaria REDEVAL y no se ha verificado ningún convenio de evaluación por encargo. | X8: Evaluación de políticas públicas: la Ley 27/2022 regula solo la AGE; cada comunidad organiza la evaluación de sus propias políticas por autoorganización, con ley propia o sin ella. La cooperación se hace por la red voluntaria REDEVAL (constituida en 2025: 13 CCAA y el Gobierno de España). | Y8: https://www.boe.es/diario_boe/txt.php?id=BOE-A-2026-2553 https://laadministracionaldia.inap.es/noticia.asp?id=1518225 https://www.boe.es/boe/dias/2026/07/28/pdfs/BOE-A-2026-16358.pdf https://laadministracionaldia.inap.es/noticia.asp?id=1516123 https://aecpa.es/files/view/pdf/congress-papers/17-0/3430 https://www.redalyc.org/journal/2815/281573431006/281573431006.pdf https://europeanevaluation.org/2026/02/05/spains-evaluation-awakening-a-decisive-momentum-from-quiet-reform-to-national-movement/
A9: Escuelas e institutos de formación de empleados públicos | B9: Instituto Nacional de Administración Pública (INAP) | C9: Propio (ente): Instituto Andaluz de Administración Pública (IAAP) | D9: Propio (órgano): Instituto Aragonés de Administración Pública (IAAP) | E9: Propio (órgano): Instituto Asturiano de Administración Pública 'Adolfo Posada' | F9: Propio (ente): Escuela Balear de Administración Pública (EBAP) | G9: Sin verificar | H9: Propio (ente): Instituto Cántabro de Administración Pública 'Rafael de la Sierra' (ICAP) | I9: Propio (órgano): Escuela de Administración Regional (EAR) | J9: Propio (órgano): Escuela de Administración Pública de Castilla y León (ECLAP) | K9: Propio (ente): Escola d'Administració Pública de Catalunya (EAPC) | L9: Sin verificar | M9: Sin verificar | N9: Propio (ente): Escola Galega de Administración Pública (EGAP) | O9: Sin verificar | P9: Propio (órgano): Escuela de Formación e Innovación de la Administración Pública de la Región de Murcia (EFIAP) | Q9: Consejería | R9: Propio (ente): Instituto Vasco de Administración Pública (IVAP) | S9: Propio (órgano): Escuela Riojana de Administración Pública (ERAP) | T9: =COUNTIF(C9:S9,"Propio*") -> 12 | U9: =COUNTIF(C9:S9,"Sin verificar") -> 4 | V9: =1+T9 -> 13 | W9: no: el INAP no forma al personal autonómico como servicio sustitutivo. Solo financia en parte (AFEDAP) y colabora con las escuelas autonómicas. | X9: Formación de empleados públicos: cada administración forma a su propio personal (autoorganización y función pública propia, TREBEP). El Estado coordina y financia en parte mediante el AFEDAP, que gestiona el INAP. | Y9: https://portal.inap.es/documents/10136/2292011/2022-MEMORIA.pdf/1f8338c1-e550-48bb-0c00-eefcbcd684af https://boe.es/boe/dias/2008/06/11/pdfs/A26873-26873.pdf
A10: Agencias de ciberseguridad | B10: INCIBE (S.M.E. Instituto Nacional de Ciberseguridad de España, sociedad mercantil estatal) y CCN-CERT (capacidad de respuesta del Centro Criptológico Nacional, integrado en el CNI) | C10: Propio (órgano): AndalucíaCERT (Centro de Seguridad TIC de Andalucía) | D10: Sin verificar | E10: Sin verificar | F10: Propio (ente): Agencia Balear de Digitalización, Ciberseguridad y Telecomunicaciones (ABDigital) | G10: Sin verificar | H10: Sin verificar | I10: Sin verificar | J10: Sin verificar | K10: Propio (ente): Agència de Ciberseguretat de Catalunya | L10: Propio (órgano): CSIRT-CV, Centro de Ciberseguridad de la Generalitat | M10: Sin verificar | N10: Propio (órgano): CSIRT.gal (Centro de Respuesta a Incidentes de Ciberseguridad de la Xunta) | O10: Propio (ente): Agencia de Ciberseguridad de la Comunidad de Madrid | P10: Sin verificar | Q10: Sin verificar | R10: Propio (ente): Agencia Vasca de Ciberseguridad (Zibersegurtasuneko Euskal Agentzia) | S10: Sin verificar | T10: =COUNTIF(C10:S10,"Propio*") -> 7 | U10: =COUNTIF(C10:S10,"Sin verificar") -> 10 | V10: =2+T10 -> 9 | W10: Sí, por ley y por defecto: el CCN-CERT ya es el CSIRT de referencia de todas las administraciones autonómicas. Varias CCAA sin agencia propia operan SOC o CSIRT integrados en la Red Nacional de SOC del CCN o con convenio con el CCN-CERT (p. ej. Baleares 2022, Galicia, Castilla y León). | X10: Seguridad pública, defensa y telecomunicaciones son competencias estatales (art. 149.1.21ª, 29ª CE). La normativa NIS (RD-ley 12/2018) designa CSIRT de referencia estatales: el CCN-CERT para el sector público y el INCIBE-CERT para el sector privado. Cada CCAA protege sus propios sistemas por autoorganización, aplicando el Esquema Nacional de Seguridad. | Y10: https://www.boe.es/eli/es-ct/l/2017/07/25/15 https://www.boe.es/diario_boe/txt.php?id=BOE-A-2023-17645 https://www.bocm.es/boletin/CM_Orden_BOCM/2026/07/14/BOCM-20260714-12.PDF https://www.caib.es/eboibfront/eli/es-ib/d/2025/12/19/63/dof/spa/pdf https://www.caib.es/sites/dgtic/es/soc/ https://sedian.juntadeandalucia.es/rfc-2350 https://laadministracionaldia.inap.es/noticia.asp?id=1515740 https://www.xunta.gal/hemeroteca/-/nova/157128/centro-respuesta-incidentes-ciberseguridad-xunta-entra-red-nacional-impulsada https://ast.aragon.es/sites/default/files/ast_memoriaactividad2016_resumen.pdf
A11: Agencias de administración digital y TIC | B11: Agencia Estatal de Administración Digital (AEAD) | C11: Propio (ente): Agencia Digital de Andalucía (ADA) | D11: Propio (ente): Aragonesa de Servicios Telemáticos (AST) | E11: Sin verificar | F11: Propio (ente): Agencia Balear de Digitalización, Ciberseguridad y Telecomunicaciones (ABDigital) | G11: Sin verificar | H11: Sin verificar | I11: Propio (ente): Agencia de Transformación Digital de Castilla-La Mancha | J11: Sin verificar | K11: Propio (ente): Centre de Telecomunicacions i Tecnologies de la Informació (CTTI) | L11: Consejería | M11: Sin verificar | N11: Propio (ente): Agencia para la Modernización Tecnológica de Galicia (AMTEGA) | O11: Propio (ente): Agencia para la Administración Digital de la Comunidad de Madrid (Madrid Digital) | P11: Propio (ente): Agencia Digital de la Región de Murcia (organismo autónomo) | Q11: Sin verificar | R11: Propio (ente): EJIE, Sociedad Informática del Gobierno Vasco, S.A. | S11: Sin verificar | T11: =COUNTIF(C11:S11,"Propio*") -> 9 | U11: =COUNTIF(C11:S11,"Sin verificar") -> 7 | V11: =1+T11 -> 10 | W11: Parcial, por adhesión voluntaria a servicios comunes de la AGE; no sustituye a los servicios TIC autonómicos. | X11: Autoorganización: cada administración gestiona sus propios sistemas de información (art. 148.1.1ª CE y estatutos). La Ley 40/2015 obliga a la interoperabilidad y permite reutilizar y adherirse a soluciones de otras administraciones. | Y11: https://www.boe.es/buscar/doc.php?id=BOE-A-2024-22929 https://www.juntadeandalucia.es/boja/2021/65/43 https://ast.aragon.es/sites/default/files/ast_memoriaactividad2016_resumen.pdf https://www.caib.es/eboibfront/eli/es-ib/d/2025/12/19/63/dof/spa/pdf https://www.boe.es/eli/es-cm/l/2024/03/15/1 https://documents.dadesobertes.gencat.cat/convenis/docs/2021/2021_5_1536/2021_5_1536_0.pdf https://pdr-mediorural.xunta.gal/sites/default/files/inline-files/D.252.11.castellano.pdf https://www.bocm.es/boletin/CM_Orden_BOCM/2026/07/14/BOCM-20260714-12.PDF https://www.boe.es/buscar/act.php?id=BORM-s-2022-90316 https://www.ejie.euskadi.eus/who-we-are/-/legal-and-corporate-framework/ https://laadministracionaldia.inap.es/noticia.asp?id=1515740
A12: Agencias de investigación e innovación | B12: Agencia Estatal de Investigación (AEI) y Centro para el Desarrollo Tecnológico y la Innovación (CDTI, E.P.E.) | C12: Consejería | D12: Propio (ente): Fundación Agencia Aragonesa para la Investigación y el Desarrollo (ARAID) | E12: Propio (ente): Agencia de Ciencia, Competitividad Empresarial e Innovación del Principado de Asturias (SEKUENS) | F12: Sin verificar | G12: Propio (órgano): Agencia Canaria de Investigación, Innovación y Sociedad de la Información (ACIISI) | H12: Sin verificar | I12: Propio (ente): Agencia de Investigación e Innovación de Castilla-La Mancha (organismo autónomo) | J12: Sin verificar | K12: Propio (ente): Agència de Gestió d'Ajuts Universitaris i de Recerca (AGAUR) | L12: Propio (ente): Agència Valenciana de la Innovació (AVI), integrada operativamente en IVACE+i | M12: Sin verificar | N12: Propio (ente): Axencia Galega de Innovación (GAIN) | O12: Sin verificar | P12: Propio (ente): Fundación Séneca, Agencia de Ciencia y Tecnología de la Región de Murcia | Q12: Sin verificar | R12: Sin verificar | S12: Sin verificar | T12: =COUNTIF(C12:S12,"Propio*") -> 8 | U12: =COUNTIF(C12:S12,"Sin verificar") -> 8 | V12: =2+T12 -> 10 | W12: Sí, en concurrencia: AEI y CDTI financian a entidades de todas las CCAA mediante convocatorias estatales; los organismos autonómicos añaden fondos propios y no cubren huecos territoriales. | X12: Fomento y coordinación general de la investigación científica y técnica: competencia estatal (art. 149.1.15ª CE). Las CCAA pueden fomentar la investigación en su territorio (art. 148.1.17ª CE y estatutos), coordinadas por la Ley 14/2011 de la Ciencia y el Consejo de Política Científica, Tecnológica y de Innovación. | Y12: https://www.boe.es/eli/es/rd/2015/11/27/1067 https://www.boe.es/eli/es/rd/2026/04/01/263 https://laadministracionaldia.inap.es/noticia.asp?id=1264632 https://www.juntadeandalucia.es/export/presup2026/memoria/memoria2-e-2.pdf https://www.boe.es/boe/dias/2019/01/28/pdfs/BOE-A-2019-994.pdf https://boe.es/buscar/doc.php?id=BOE-A-2023-1605 https://www.gobiernodecanarias.org/conocimiento/la_agencia/ https://castillalamancha.es/sites/default/files/documentos/pdf/20220629/08_decreto_54_2022_estatutos_agencia_investigacion.pdf https://laadministracionaldia.inap.es/noticia.asp?id=1266605 https://www.uv.es/serinves/convocatories/2026/Avi%202026/instruccions_internes.pdf https://www.xunta.gal/dog/Publicados/2012/20120127/AnuncioCA04-230112-11332_es.html https://www.borm.es/services/anuncio/ano/2026/numero/2481/pdf?id=843163
A13: Agencias de la energía | B13: Instituto para la Diversificación y Ahorro de la Energía (IDAE) | C13: Propio (ente): Agencia Andaluza de la Energía | D13: Consejería | E13: Propio (ente): Fundación Asturiana de la Energía (FAEN) | F13: Propio (ente): Instituto Balear de la Energía (IBE) | G13: Consejería | H13: Sin verificar | I13: Sin verificar | J13: Propio (ente): Ente Regional de la Energía de Castilla y León (EREN) | K13: Propio (ente): Institut Català d'Energia (ICAEN) | L13: Propio (ente): IVACE+i (Instituto Valenciano de Competitividad e Innovación), área de Energía | M13: Propio (ente): Agencia Extremeña de la Energía (AGENEX), entidad pública empresarial | N13: Propio (ente): Instituto Enerxético de Galicia (INEGA) | O13: Propio (ente): Fundación de la Energía de la Comunidad de Madrid (FENERCOM) | P13: Consejería | Q13: Consejería | R13: Propio (ente): Ente Vasco de la Energía (EVE) | S13: Consejería | T13: =COUNTIF(C13:S13,"Propio*") -> 10 | U13: =COUNTIF(C13:S13,"Sin verificar") -> 2 | V13: =1+T13 -> 11 | W13: Parcial: el IDAE actúa en todo el territorio, pero buena parte de sus líneas se ejecutan a través de las CCAA (consejería o agencia regional). Donde no hay agencia, la gestiona la consejería. | X13: Bases del régimen energético y planificación económica general: competencias estatales (art. 149.1.13ª y 25ª CE). A las CCAA corresponden el desarrollo normativo y la ejecución, incluida la gestión de ayudas de ahorro, eficiencia y renovables en su territorio. | Y13: https://www.cnmc.es/sites/default/files/energia/consumidores/201610_Enlaces%2520eficiencia%2520energ%C3%A9tica%5B1%5D.pdf https://juntadeandalucia.es/boja/2003/189/1 https://www.boe.es/buscar/pdf/2019/BOE-A-2019-5579-consolidado.pdf https://www.gobiernodecanarias.org/boc/2022/257/001.html https://derecholocal.es/?p=13612 https://laadministracionaldia.inap.es/noticia.asp?id=1241987 https://www.boe.es/diario_boe/txt.php?id=BOE-A-2026-15131 https://laadministracionaldia.inap.es/noticia.asp?id=1111574 https://transparencia.carm.es/wres/transparencia/doc/Consejo_Gobierno/2018-06-14/punto_25_ENERAGEN.pdf https://www.boe.es/buscar/act.php?id=BOE-A-2024-1778 https://www.boe.es/eli/es-ri/l/2022/11/02/13
A14: Seguridad ferroviaria | B14: Agencia Estatal de Seguridad Ferroviaria (AESF) | C14: Sin verificar | D14: Lo cubre el Estado | E14: Lo cubre el Estado | F14: Sin verificar | G14: No existe | H14: Lo cubre el Estado | I14: Lo cubre el Estado | J14: Lo cubre el Estado | K14: Consejería | L14: Propio (ente): Agència Valenciana de Seguretat Ferroviària (AVSF) | M14: Lo cubre el Estado | N14: Lo cubre el Estado | O14: Sin verificar | P14: Lo cubre el Estado | Q14: Lo cubre el Estado | R14: No existe | S14: Lo cubre el Estado | T14: =COUNTIF(C14:S14,"Propio*") -> 1 | U14: =COUNTIF(C14:S14,"Sin verificar") -> 3 | V14: =1+T14 -> 2 | W14: Parcial. La AESF cubre por ley toda la RFIG en las 17 CCAA. No cubre las redes autonómicas (FGC, FGV, Euskotren, SFM) ni metros y tranvías: su informe 2025 los excluye y en Madrid la propia AESF declara que no tiene competencia sobre Metro. No se ha encontrado ninguna encomienda o convenio por el que la AESF supervise una red autonómica. Extenderla requeriría un convenio o una encomienda con cada comunidad, o un cambio legal. | X14: Los ferrocarriles que discurren íntegramente por el territorio de una comunidad son de competencia autonómica (art. 148.1.5ª CE y estatutos). La RFIG y su seguridad son estatales (art. 149.1.21ª CE; Ley 38/2015, del Sector Ferroviario, con la AESF como autoridad de seguridad). | Y14: https://www.boe.es/eli/es/rd/2014/12/19/1072 https://www.era.europa.eu/sites/default/files/reports/ias%20nsa%20espa%C3%B1a%202025.pdf https://www.boe.es/eli/es-vc/l/2018/03/26/7/con https://www.boe.es/ccaa/dogv/2026/10425/r00001-00351.pdf https://www.boe.es/ccaa/dogc/2026/9680/f00001-00004.pdf https://www.euskadi.eus/contenidos/anuncio_tablon/con_3917055/es_def/adjuntos/Orden-consulta-publica-previa-LSF.pdf
A15: Agencias de salud pública | B15: Agencia Estatal de Salud Pública (AESAP) | C15: Consejería | D15: Consejería | E15: Consejería | F15: Propio (ente): Agencia de Salud Pública de las Illes Balears (ASPIB) | G15: Consejería | H15: Consejería | I15: Consejería | J15: Consejería | K15: Propio (órgano): Agència de Salut Pública de Catalunya (ASPCAT), sin personalidad jurídica | L15: Consejería | M15: Consejería | N15: Consejería | O15: Consejería | P15: Consejería | Q15: Propio (ente): Instituto de Salud Pública y Laboral de Navarra (ISPLN) | R15: Propio (ente): Instituto Vasco de Salud Pública (Osasungintza) | S15: Consejería | T15: =COUNTIF(C15:S15,"Propio*") -> 4 | U15: =COUNTIF(C15:S15,"Sin verificar") -> 0 | V15: =1+T15 -> 5 | W15: No. La AESAP no sustituye a las direcciones generales ni a las agencias autonómicas: la vigilancia y la intervención de salud pública siguen siendo autonómicas. Solo coordina e integra la información. | X15: Sanidad: bases y coordinación general son estatales (art. 149.1.16ª CE); la gestión de la salud pública es autonómica (estatutos; Ley 33/2011, General de Salud Pública). La AESAP es un órgano estatal de vigilancia, preparación y coordinación y no asume la ejecución autonómica. | Y15: https://www.boe.es/eli/es/l/2025/07/28/7 https://www.sanidad.gob.es/en/profesionales/saludPublica/saludAmbLaboral/calidadAguas/piscinas/pdf/CCAA_SILOE_R_ene21.pdf https://www.boe.es/buscar/act.php?id=BOE-A-2011-2108 https://www.euskadi.eus/web01-bopv/es/bopv2/datos/2023/12/2305490a.shtml https://govern.cat/govern/docs/2017/10/24/16/16/6bc122b4-de02-4974-9a53-0974dfdc3a37.pdf https://aplicacions.economia.gencat.cat/wpres/2023/pdf/MP_SA14.pdf
A16: Agencias de cooperación al desarrollo | B16: Agencia Española de Cooperación Internacional para el Desarrollo (AECID) | C16: Propio (ente): Agencia Andaluza de Cooperación Internacional para el Desarrollo (AACID) | D16: Sin verificar | E16: Propio (órgano): Agencia Asturiana de Cooperación al Desarrollo | F16: Sin verificar | G16: Sin verificar | H16: Sin verificar | I16: Sin verificar | J16: Sin verificar | K16: Propio (ente): Agència Catalana de Cooperació al Desenvolupament (ACCD) | L16: Sin verificar | M16: Propio (ente): Agencia Extremeña de Cooperación Internacional para el Desarrollo (AEXCID) | N16: Sin verificar | O16: Sin verificar | P16: Sin verificar | Q16: Sin verificar | R16: Propio (ente): Agencia Vasca de Cooperación para el Desarrollo (eLankidetza) | S16: Sin verificar | T16: =COUNTIF(C16:S16,"Propio*") -> 5 | U16: =COUNTIF(C16:S16,"Sin verificar") -> 12 | V16: =1+T16 -> 6 | W16: No por defecto. Las CCAA gestionan su propia AOD. La AECID podría canalizar fondos autonómicos mediante convenio (hay convenios puntuales, p. ej. Murcia-AECID 2017 según el Consejo de Gobierno de la CARM), pero no hay cobertura general. | X16: La política de cooperación internacional del Estado deriva del art. 149.1.3ª CE. La Ley 1/2023, de Cooperación para el Desarrollo Sostenible y la Solidaridad Global, reconoce la cooperación descentralizada de CCAA y entes locales (cap. IV, sección 2ª), que estas financian y gestionan con fondos propios. | Y16: https://www.boe.es/eli/es/rd/2007/10/26/1403/con https://www.juntadeandalucia.es/boja/2006/98/d2.pdf https://euskadi.eus:443/bopv2/datos/2008/07/0804175a.pdf https://doe.juntaex.es/pdfs/doe/2024/1420o/24062490.pdf https://www.asturias.es/bopa/2026/06/15/2026-04797.pdf
A17: Institutos de seguridad y salud laboral | B17: Instituto Nacional de Seguridad y Salud en el Trabajo (INSST, O.A., M.P.) | C17: Propio (ente): Instituto Andaluz de Prevención de Riesgos Laborales (IAPRL) | D17: Propio (órgano): Instituto Aragonés de Seguridad y Salud Laboral (ISSLA) | E17: Propio (ente): Instituto Asturiano de Prevención de Riesgos Laborales (IAPRL) | F17: Propio (ente): Instituto Balear de Seguridad y Salud Laboral (IBASSAL) | G17: Propio (ente): Instituto Canario de Seguridad Laboral (ICASEL) | H17: Propio (ente): Instituto Cántabro de Seguridad y Salud en el Trabajo (ICASST) | I17: Consejería | J17: Consejería | K17: Consejería | L17: Propio (ente): Instituto Valenciano de Seguridad y Salud en el Trabajo (INVASSAT) | M17: Consejería | N17: Propio (ente): Instituto de Seguridad y Salud Laboral de Galicia (ISSGA) | O17: Propio (ente): Instituto Regional de Seguridad y Salud en el Trabajo (IRSST) | P17: Propio (ente): Instituto de Seguridad y Salud Laboral de la Región de Murcia (ISSL) | Q17: Propio (ente): Instituto de Salud Pública y Laboral de Navarra (ISPLN) | R17: Propio (ente): Instituto Vasco de Seguridad y Salud Laborales (OSALAN) | S17: Consejería | T17: =COUNTIF(C17:S17,"Propio*") -> 12 | U17: =COUNTIF(C17:S17,"Sin verificar") -> 0 | V17: =1+T17 -> 13 | W17: No. La ejecución está transferida a las 17 CCAA, que la ejercen con institutos propios o desde la consejería. El INSST no presta esos servicios en territorio autonómico; solo hace investigación, normalización y estudios estatales y coordina. | X17: Legislación laboral estatal; su ejecución corresponde a las CCAA (art. 149.1.7ª CE). La Ley 31/1995, de PRL, encarga al INSST el apoyo técnico y la colaboración con los órganos técnicos autonómicos, que ejercen el asesoramiento, la investigación de accidentes y el apoyo técnico a la ITSS en su territorio. | Y17: https://www.insst.es/el-instituto/conoce-el-instituto/mision-y-funciones https://www.insst.es/relaciones-institucionales/ambito-autonomico/enlaces-organismos-ccaa-en-prl-con-estrategias-sst https://juntadeandalucia.es/boja/2006/251/2 https://cdn.juntadeandalucia.es/boja/2020/4/BOJA20-004-00002-31-01_00167569.pdf https://intranet.caib.es/eboibfront/pdf/es/2024/89/1166156 https://laadministracionaldia.inap.es/noticia.asp?id=1225149
A18: Entes de emergencias 112 | B18: Dirección General de Protección Civil y Emergencias (Ministerio del Interior) | C18: Propio (ente): Agencia de Emergencias de Andalucía (antes Agencia de Seguridad y Gestión Integral de Emergencias, ASGIE) | D18: Sin verificar | E18: Propio (ente): Servicio de Emergencias del Principado de Asturias (SEPA) | F18: Propio (ente): Gestió d'Emergències de les Illes Balears (GEIB), entidad pública empresarial | G18: Propio (ente): Gestión de Servicios para la Salud y Seguridad en Canarias (GSC), sociedad pública | H18: Propio (ente): Servicio de Emergencias de Cantabria (SEMCA), organismo autónomo | I18: Sin verificar | J18: Consejería | K18: Propio (ente): Centre d'Atenció i Gestió de Trucades d'Urgència 112 Catalunya (CAT112), entidad de derecho público | L18: Propio (ente): Agència Valenciana de Seguretat i Resposta a les Emergències (AVSRE), organismo autónomo | M18: Sin verificar | N18: Propio (ente): Axencia Galega de Emerxencias (AXEGA), agencia pública autonómica | O18: Propio (ente): Agencia de Seguridad y Emergencias Madrid 112 (ASEM112), ente de derecho público de régimen especial | P18: Sin verificar | Q18: Consejería | R18: Sin verificar | S18: Sin verificar | T18: =COUNTIF(C18:S18,"Propio*") -> 9 | U18: =COUNTIF(C18:S18,"Sin verificar") -> 6 | V18: =0+T18 -> 9 | W18: No. El Estado no presta el 112 en ninguna comunidad: los 17 centros 112 son autonómicos. La duplicación es entre comunidades, en la forma de gestionar (ente o servicio), no con el Estado. | X18: Protección civil: competencia concurrente. Las CCAA prestan el servicio 112 y gestionan las emergencias de su ámbito (RD 903/1997; estatutos); el Estado gestiona las emergencias de interés nacional y coordina el sistema (Ley 17/2015, del Sistema Nacional de Protección Civil). | Y18: https://www.boe.es/eli/es/l/2015/07/09/17 https://laadministracionaldia.inap.es/noticia.asp?id=1246471 https://laadministracionaldia.inap.es/noticia.asp?id=1265294 https://laadministracionaldia.inap.es/noticia.asp?id=1250448 https://ficheiros-web.xunta.gal/cartas_de_servizo/aprobadas/emerxencias/Carta_Servizos_gal.pdf https://intranet.caib.es/eboibfront/pdf/ca/2026/30/1214222 https://parcan.es/files/pub/bop/11l/2024/417/bo417.pdf https://laadministracionaldia.inap.es/noticia.asp?id=1267282 https://laadministracionaldia.inap.es/noticia.asp?id=1267294
A19: Observatorios de convivencia escolar | B19: Observatorio Estatal de la Convivencia Escolar | C19: Propio (órgano): Observatorio para la Convivencia Escolar en Andalucía | D19: Propio (órgano): Observatorio autonómico de convivencia escolar de Aragón (el informe no da el nombre exacto) | E19: Propio (órgano): Observatorio autonómico de convivencia escolar del Principado de Asturias (el informe no da el nombre exacto) | F19: Propio (órgano): Institut per a la Convivència i l'Èxit Escolar (Convivèxit) | G19: Sin verificar | H19: Propio (órgano): Observatorio autonómico de convivencia escolar de Cantabria (el informe no da el nombre exacto) | I19: Propio (órgano): Observatorio autonómico de convivencia escolar de Castilla-La Mancha (el informe no da el nombre exacto) | J19: Propio (órgano): Observatorio de la Comunidad de Castilla y León, sección de convivencia escolar | K19: Sin verificar | L19: Propio (órgano): Observatorio para la Convivencia Escolar (desde 2023, pleno conjunto «Observatorio Igualdad y Convivencia») | M19: Propio (órgano): Observatorio para la Convivencia Escolar en Extremadura | N19: Propio (órgano): Consejo para la Convivencia Escolar de la Comunidad Autónoma de Galicia | O19: Propio (órgano): Observatorio autonómico de convivencia escolar de la Comunidad de Madrid (el informe no da el nombre exacto) | P19: Propio (órgano): Observatorio autonómico de convivencia escolar de la Región de Murcia (el informe no da el nombre exacto) | Q19: Sin verificar | R19: Propio (órgano): Observatorio autonómico de convivencia escolar del País Vasco (el informe no da el nombre exacto) | S19: Propio (órgano): Observatorio autonómico de convivencia escolar de La Rioja (el informe no da el nombre exacto) | T19: =COUNTIF(C19:S19,"Propio*") -> 14 | U19: =COUNTIF(C19:S19,"Sin verificar") -> 3 | V19: =1+T19 -> 15 | W19: Parcial. El Observatorio Estatal (RD 275/2007, modificado por RD 3/2018) es un órgano colegiado consultivo de ámbito estatal: estudia, informa y propone. No gestiona la convivencia en los centros, que corresponde a las CCAA, y no hay convenios para que cubra a una CCAA sin observatorio propio. | X19: Educación: el Estado dicta las normas básicas (art. 149.1.30 CE, LOE/LOMLOE) y las CCAA las desarrollan, ejecutan y gestionan los centros. Cada administración educativa puede crear sus propios órganos de convivencia; ninguna ley lo obliga. | Y19: https://educacionfpydeportes.gob.es/dam/jcr:9b630aa5-b767-4739-848b-65a46bcebbf9/informe-convivencia-ccaa-v-mayo--2024.pdf https://educacionfpydeportes.gob.es/ca/dam/jcr:6e1130b2-96f3-4008-b2ab-c6dbb76d473f/rd-observatorio-estatal-convivencia-escolar.pdf https://vlex.es/vid/real-decreto-3-2018-700920453 https://sirdoc.ccyl.es/Biblioteca/Dosieres/DL203AtencionViolenciaGenero/pdfs/CyL-Decreto-52-2014-Observatorio.pdf https://doe.juntaex.es/pdfs/doe/2026/1040o/26050065.pdf https://www.caib.es/sites/convivexit/ca/normativa_autonamica/
A20: Consejos de la juventud | B20: Consejo de la Juventud de España (CJE) | C20: Propio (órgano): Consejo de la Juventud de Andalucía | D20: Propio (ente): Consejo de la Juventud de Aragón | E20: Propio (ente): Consejo de la Juventud del Principado de Asturias (Conseyu de la Mocedá) | F20: Sin verificar | G20: Sin verificar | H20: Propio (ente): Consejo de la Juventud de Cantabria | I20: Propio (ente): Consejo de la Juventud de Castilla-La Mancha | J20: Propio (ente): Consejo de la Juventud de Castilla y León | K20: Sin verificar | L20: Sin verificar | M20: Propio (ente): Consejo de la Juventud de Extremadura | N20: Propio (órgano): Consejo Asesor y Consultivo de Juventud de Galicia | O20: Propio (órgano): Mesa de Políticas de Juventud de la Comunidad de Madrid (sustituye al Consejo de la Juventud, suprimido) | P20: Sin verificar | Q20: Propio (ente): Consejo de la Juventud de Navarra / Nafarroako Gazteriaren Kontseilua | R20: Sin verificar | S20: Propio (ente): Consejo de la Juventud de La Rioja | T20: =COUNTIF(C20:S20,"Propio*") -> 11 | U20: =COUNTIF(C20:S20,"Sin verificar") -> 6 | V20: =1+T20 -> 12 | W20: No sustitutiva. El CJE es una plataforma estatal; tras la Ley 15/2014 (reforma CORA) dejó de ser organismo autónomo y es una entidad corporativa de base privada. Los consejos autonómicos forman parte de él o se coordinan con él, pero no representa a la juventud ante cada gobierno autonómico. No hay convenios de cobertura. | X20: Juventud: es una competencia exclusiva autonómica según los Estatutos. El art. 48 CE obliga a todos los poderes públicos a promover la participación de la juventud. Cada CCAA regula su consejo por ley propia; el CJE actúa en el ámbito estatal. | Y20: https://www.cje.org/en/entidades/ https://www.cje.org/en/faq/ https://www.boe.es/eli/es-cb/l/2019/02/14/1/con/20190225 https://www.boe.es/boe/dias/2005/05/20/pdfs/A16971-16975.pdf https://boe.es/boe/dias/2025/03/20/pdfs/BOE-A-2025-5523.pdf https://laadministracionaldia.inap.es/noticia.asp?id=1127756 https://laadministracionaldia.inap.es/noticia.asp?id=1235364 https://www.boe.es/boe/dias/1985/05/22/pdfs/A14960-14961.pdf https://www.parcan.es/files/documentacion/dosieres/DOSS0102/DOSS0102DOC1424.PDF https://tematico.asturias.es/hacienda/cuen2005/doc/5/4_1.pdf https://www.juntadeandalucia.es/sites/default/files/2020-03/Proyecto%20de%20Ley%20de%20Juventud%20de%20Andaluc%C3%ADa.pdf https://www.cje.org/download/295/consejos-de-juventud/23033/res-2016-autonomiacjandalucia.pdf
A21: Observatorios de igualdad y violencia de género | B21: Observatorio Estatal de Violencia sobre la Mujer | C21: Propio (órgano): Observatorio Andaluz de la Violencia de Género | D21: Propio (órgano): Observatorio Aragonés de Violencia sobre la Mujer | E21: Sin verificar | F21: Propio (órgano): Observatori per a la Igualtat de les Illes Balears | G21: Propio (órgano): Observatorio de la Igualdad de Género (Instituto Canario de Igualdad) | H21: Propio (órgano): Observatorio de Igualdad de Género de Cantabria | I21: Sin verificar | J21: Propio (órgano): Observatorio de la Comunidad de Castilla y León, sección de género | K21: Propio (órgano): Observatori de la Igualtat de Gènere (OIG) | L21: Sin verificar | M21: Sin verificar | N21: Propio (órgano): Observatorio Galego da Violencia de Xénero | O21: Propio (órgano): Observatorio Regional de la Violencia de Género | P21: Propio (órgano): Observatorio de Igualdad de la Región de Murcia | Q21: Sin verificar | R21: Sin verificar | S21: Sin verificar | T21: =COUNTIF(C21:S21,"Propio*") -> 10 | U21: =COUNTIF(C21:S21,"Sin verificar") -> 7 | V21: =1+T21 -> 11 | W21: Parcial. El OEVM (LO 1/2004, art. 30; RD 253/2006) es un órgano colegiado adscrito al Ministerio de Igualdad que elabora informes de ámbito estatal. No hay convenios para que sustituya a los observatorios autonómicos. Sin presupuesto propio: el gasto lo asume la DG contra la Violencia de Género (lote previo B1). | X21: Igualdad y violencia de género: el Estado fija el marco básico (LO 1/2004 y LO 3/2007; art. 149.1.1 CE) y las CCAA tienen competencias propias en políticas de mujer y asistencia social según sus Estatutos y leyes autonómicas. Cada CCAA puede crear sus órganos de seguimiento. | Y21: https://www.boe.es/eli/es/lo/2004/12/28/1 https://www.boe.es/eli/es/rd/2006/03/03/253/con/20220928 https://cdn.juntadeandalucia.es/boja/2010/116/d2.pdf https://www.parcan.es/files/documentacion/dosieres/DOSS0244/DOSS0244DOC5684.PDF https://www.caib.es/sites/participacio/es/n/observatori_per_a_la_igualtat/ https://vlex.es/vid/decreto-38-2015-27-563806338 https://sirdoc.ccyl.es/Biblioteca/Dosieres/DL203AtencionViolenciaGenero/pdfs/CyL-Decreto-52-2014-Observatorio.pdf https://dones.gencat.cat/content/dam/dones/03_ambits/observatori/01_coneix_nos/activitats/Memoria-OIG-2025_edicio.pdf https://www.lex.gal/es/normativa/detalle/3166/pdf/ https://www.bocm.es/boletin/CM_Orden_BOCM/2022/12/21/BOCM-20221221-47.PDF https://borm.es/services/anuncio/782935/pdf https://transparencia.carm.es/documents/184026/11587769/MAIN+Decreto+Observatorio+Igualdad.pdf/fb2f0a04-7b0e-47f6-a68f-6948b430238a https://www.boe.es/eli/es-nc/lf/2019/04/04/17/con
A22: Consejos audiovisuales (reguladores) | B22: Comisión Nacional de los Mercados y la Competencia (CNMC) | C22: Propio (ente): Consejo Audiovisual de Andalucía (CAA) | D22: Sin verificar | E22: Sin verificar | F22: Sin verificar | G22: Sin verificar | H22: Sin verificar | I22: Sin verificar | J22: Sin verificar | K22: Propio (ente): Consell de l'Audiovisual de Catalunya (CAC) | L22: Propio (ente): Consell de l'Audiovisual de la Comunitat Valenciana | M22: Sin verificar | N22: Sin verificar | O22: Consejería | P22: Sin verificar | Q22: Consejería | R22: Sin verificar | S22: Sin verificar | T22: =COUNTIF(C22:S22,"Propio*") -> 3 | U22: =COUNTIF(C22:S22,"Sin verificar") -> 12 | V22: =1+T22 -> 4 | W22: No. La CNMC asumió la regulación audiovisual estatal en 2013 (Ley 3/2013) y supervisa a los prestadores de ámbito estatal. Los prestadores autonómicos y locales los supervisa la autoridad de cada CCAA, sea un consejo independiente o la propia consejería. No hay convenios para que la CNMC cubra a una CCAA. | X22: Audiovisual: el Estado fija las bases del régimen de radio y televisión (art. 149.1.27 CE; Ley 13/2022, General de Comunicación Audiovisual) y las CCAA las desarrollan y ejecutan. La supervisión se reparte según el ámbito de cobertura del prestador. | Y22: https://www.cnmc.es/en/ambitos-de-actuacion/audiovisual/actividad-internacional https://www.rirm.org/en/caa-audiovisual-council-of-andalusia/ https://vlex.es/vid/decreto-121-2022-16-910713792 https://redopositor.com/oposiciones/convocatoria/resolucio-de-14-de-juliol-de-2026-de-la-presidencia-per-la-qual-es-pro--00d7ce64/ https://www.boe.es/eli/es-md/l/2001/04/18/2/con/20231229 https://parlamentodenavarra.es/sites/default/files/boletines/B2011821.pdf https://www.boe.es/eli/es-ib/l/2010/12/22/15/con
A24: Rojo: la comunidad tiene organismo propio sobre el tema. Verde: no lo tiene (lo cubre el Estado, lo hace la consejería o no existe). Gris: sin verificar. "Organismos en total" suma el estatal y los autonómicos verificados; el máximo posible es 18. Fuentes oficiales por celda en el dashboard y en los JSON de trabajo.

Sheet Hoja 1
